<?xml version="1.0" encoding="utf-8"?>
<robot name="S03_ROBOT_v2_dual_ar5_hands">
  <material name="orange">
    <color rgba="0.5 0.0 0.5 1.0"/>
  </material>
  <material name="chassis_silver">
    <color rgba="0.78 0.80 0.82 1.0"/>
  </material>
  <material name="body_color">
    <color rgba="0.50 0.60 0.10 1.0"/>
  </material>
  <material name="metal_dark">
    <color rgba="0.35 0.38 0.36 0.7"/>
  </material>
  <material name="mat_black">
    <color rgba="0.05 0.05 0.06 1.0"/>
  </material>
  <material name="accent_blue">
    <color rgba="0.06 0.24 0.80 1.0"/>
  </material>
  <material name="white">
    <color rgba="1.0 1.0 1.0 1.0"/>
  </material>
  <material name="red">
    <color rgba="1 0.0 0.0 1.0"/>
  </material>
  <link name="world"/>
  <joint name="world_to_base_link" type="fixed">
    <parent link="world"/>
    <child link="base_link"/>
    <origin xyz="-0.008 0.0025066 0.2279263" rpy="0 0 0"/>
  </joint>
  <link name="base_link">
    <inertial>
      <origin xyz="0.0070854799881625 -0.00538108037871143 -0.0622819266086489" rpy="0 0 0"/>
      <mass value="15.4302699863135"/>
      <inertia ixx="0.262619030873408" ixy="-0.00015665050715054" ixz="-0.000418702441940762" iyy="0.246794795829729" iyz="-1.79168789629256E-05" izz="0.396247666954898"/>
    </inertial>
    <visual>
      <origin xyz="0 0 0" rpy="0 0 0"/>
      <geometry>
        <mesh filename="package://robot_model/meshes/base_link.STL"/>
      </geometry>
      <material name="">
        <color rgba="1 1 1 1"/>
      </material>
    </visual>
    <collision>
      <origin xyz="0 0 0" rpy="0 0 0"/>
      <geometry>
        <mesh filename="package://robot_model/meshes/base_link.STL"/>
      </geometry>
    </collision>
  </link>
  <link name="lift_1">
    <inertial>
      <origin xyz="-8.94284646335564E-14 -2.59625654308593E-13 0.229941331560846" rpy="0 0 0"/>
      <mass value="2.0172556806039"/>
      <inertia ixx="0.0395089606184288" ixy="-2.32845494008253E-20" ixz="-3.64330376707467E-18" iyy="0.0359387392625448" iyz="5.81321373760667E-19" izz="0.0132826039903637"/>
    </inertial>
    <visual>
      <origin xyz="0 0 0" rpy="0 0 0"/>
      <geometry>
        <mesh filename="package://robot_model/meshes/lift_1.STL"/>
      </geometry>
      <material name="">
        <color rgba="0.792156862745098 0.819607843137255 0.933333333333333 1"/>
      </material>
    </visual>
    <collision>
      <origin xyz="0 0 0" rpy="0 0 0"/>
      <geometry>
        <mesh filename="package://robot_model/meshes/lift_1.STL"/>
      </geometry>
    </collision>
  </link>
  <joint name="lift_11" type="prismatic">
    <origin xyz="0 0 0" rpy="0 0 0"/>
    <parent link="base_link"/>
    <child link="lift_1"/>
    <axis xyz="0 0 1"/>
    <limit lower="0" upper="0.2" effort="0" velocity="0"/>
  </joint>
  <link name="lift_2">
    <inertial>
      <origin xyz="7.55617790559882E-13 0.240253034398263 2.58459920132736E-13" rpy="0 0 0"/>
      <mass value="2.03453037752301"/>
      <inertia ixx="0.0379062410471559" ixy="3.86731651717003E-17" ixz="-9.97580351308932E-13" iyy="0.00986323316432402" iyz="1.70812378632769E-17" izz="0.040974937053481"/>
    </inertial>
    <visual>
      <origin xyz="0 0 0" rpy="0 0 0"/>
      <geometry>
        <mesh filename="package://robot_model/meshes/lift_2.STL"/>
      </geometry>
      <material name="">
        <color rgba="0.792156862745098 0.819607843137255 0.933333333333333 1"/>
      </material>
    </visual>
    <collision>
      <origin xyz="0 0 0" rpy="0 0 0"/>
      <geometry>
        <mesh filename="package://robot_model/meshes/lift_2.STL"/>
      </geometry>
    </collision>
  </link>
  <joint name="lift_22" type="prismatic">
    <origin xyz="0 0 -0.03" rpy="0 0 0"/>
    <parent link="lift_1"/>
    <child link="lift_2"/>
    <axis xyz="0 0 1"/>
    <limit lower="0" upper="0.2" effort="0" velocity="0"/>
  </joint>
  <link name="waist">
    <inertial>
      <origin xyz="7.8624075762368E-05 0.0433772700074607 -7.5418542875183E-05" rpy="0 0 0"/>
      <mass value="0.472988389284872"/>
      <inertia ixx="0.000481462643624715" ixy="-1.85553686745678E-06" ixz="-9.03279944248913E-07" iyy="0.000466157356435184" iyz="1.80076455518928E-06" izz="0.000481221158656046"/>
    </inertial>
    <visual>
      <origin xyz="0 0 0" rpy="0 0 0"/>
      <geometry>
        <mesh filename="package://robot_model/meshes/waist.STL"/>
      </geometry>
      <material name="">
        <color rgba="1 1 1 1"/>
      </material>
    </visual>
    <collision>
      <origin xyz="0 0 0" rpy="0 0 0"/>
      <geometry>
        <mesh filename="package://robot_model/meshes/waist.STL"/>
      </geometry>
    </collision>
  </link>
  <joint name="waist_joint" type="revolute">
    <origin xyz="0 0 0.50694" rpy="1.57 0 1.57"/>
    <parent link="lift_2"/>
    <child link="waist"/>
    <axis xyz="0 1 0"/>
    <limit lower="-3.14" upper="3.14" effort="0" velocity="0"/>
  </joint>
  <link name="robot_base_link"/>
  <joint name="robot_base_joint" type="fixed">
    <origin xyz="0 0 0" rpy="-0.785398 -1.56967 -0.785398"/>
    <parent link="waist"/>
    <child link="robot_base_link"/>
  </joint>
  <link name="torso_1">
    <inertial>
      <origin xyz="8.28618683608728E-05 0.373276719997577 0.00206092979079367" rpy="0 0 0"/>
      <mass value="3.45730958292012"/>
      <inertia ixx="0.0168793780947978" ixy="2.61494129983783E-06" ixz="-1.24544755597116E-07" iyy="0.0196657637637743" iyz="0.000150740519802542" izz="0.0241583685308415"/>
    </inertial>
    <visual>
      <origin xyz="0 0 0" rpy="0 0 0"/>
      <geometry>
        <mesh filename="package://robot_model/meshes/torso_1.STL"/>
      </geometry>
      <material name="">
        <color rgba="0.592156862745098 0.666666666666667 0.682352941176471 1"/>
      </material>
    </visual>
    <collision>
      <origin xyz="0 0 0" rpy="0 0 0"/>
      <geometry>
        <mesh filename="package://robot_model/meshes/torso_1.STL"/>
      </geometry>
    </collision>
  </link>
  <joint name="torso_joint" type="fixed">
    <origin xyz="0 0 0" rpy="0 0 0"/>
    <parent link="waist"/>
    <child link="torso_1"/>
    <axis xyz="0 0 0"/>
    <limit lower="-3.14" upper="3.14" effort="0" velocity="0"/>
  </joint>
  <link name="head_1">
    <inertial>
      <origin xyz="5.8371548344871E-08 0.0323993084088672 0.00827616943655801" rpy="0 0 0"/>
      <mass value="0.158702211484767"/>
      <inertia ixx="4.11206034436803E-05" ixy="6.00870718061759E-08" ixz="-2.37196209013983E-08" iyy="4.25047425254873E-05" iyz="-2.66707308907812E-06" izz="5.35896606273192E-05"/>
    </inertial>
    <visual>
      <origin xyz="0 0 0" rpy="0 0 0"/>
      <geometry>
        <mesh filename="package://robot_model/meshes/head_1.STL"/>
      </geometry>
      <material name="">
        <color rgba="1 1 1 1"/>
      </material>
    </visual>
    <collision>
      <origin xyz="0 0 0" rpy="0 0 0"/>
      <geometry>
        <mesh filename="package://robot_model/meshes/head_1.STL"/>
      </geometry>
    </collision>
  </link>
  <joint name="head_joint_1" type="revolute">
    <origin xyz="0 0.652 -0.015" rpy="3.1416 -1.5708 3.141"/>
    <parent link="torso_1"/>
    <child link="head_1"/>
    <axis xyz="0 1 0"/>
    <limit lower="-3.14" upper="3.14" effort="0" velocity="0"/>
  </joint>
  <link name="head_2">
    <inertial>
      <origin xyz="0.00736648749468191 -0.0433836436154645 0.115440559955658" rpy="0 0 0"/>
      <mass value="0.777143258094614"/>
      <inertia ixx="0.00366612316440717" ixy="1.0776138899671E-06" ixz="-0.000103269174793706" iyy="0.00277163298356202" iyz="9.41819885311698E-06" izz="0.00260766967333395"/>
    </inertial>
    <visual>
      <origin xyz="0 0 0" rpy="0 0 0"/>
      <geometry>
        <mesh filename="package://robot_model/meshes/head_2.STL"/>
      </geometry>
      <material name="">
        <color rgba="1 1 1 1"/>
      </material>
    </visual>
    <collision>
      <origin xyz="0 0 0" rpy="0 0 0"/>
      <geometry>
        <mesh filename="package://robot_model/meshes/head_2.STL"/>
      </geometry>
    </collision>
  </link>
  <joint name="head_joint_2" type="revolute">
    <origin xyz="0 0.036 0.044" rpy="1.5708 0 -3.1416"/>
    <parent link="head_1"/>
    <child link="head_2"/>
    <axis xyz="0 -1 0"/>
    <limit lower="-3.14" upper="3.14" effort="0" velocity="0"/>
  </joint>
  <link name="head_camera">
    <inertial>
      <origin xyz="-5.58678075261998E-05 0.000484008154398752 0.0126489099758612" rpy="0 0 0"/>
      <mass value="0.0246271094898963"/>
      <inertia ixx="3.41808016824083E-05" ixy="-6.4104020355105E-08" ixz="8.04356033724446E-09" iyy="3.03876162066051E-06" iyz="-2.49463938154694E-08" izz="3.66010853800153E-05"/>
    </inertial>
    <visual>
      <origin xyz="0 0 0" rpy="0 0 3.1416"/>
      <geometry>
        <mesh filename="package://robot_model/meshes/head_camera.STL"/>
      </geometry>
      <material name="">
        <color rgba="1 1 1 1"/>
      </material>
    </visual>
    <collision>
      <origin xyz="0 0 0" rpy="0 0 3.1416"/>
      <geometry>
        <mesh filename="package://robot_model/meshes/head_camera.STL"/>
      </geometry>
    </collision>
  </link>
  <joint name="head_camera" type="fixed">
    <origin xyz="-0.055446 -0.044463 0.11451" rpy="1.5708 -1.5708 -1.5708"/>
    <parent link="head_2"/>
    <child link="head_camera"/>
    <axis xyz="0 0 0"/>
  </joint>
  <link name="head_camera_frame"/>
  <joint name="head_camera_frame_joint" type="fixed">
    <origin xyz="0.00006 -0.025 0.0259" rpy="0 0 1.5708"/>
    <parent link="head_camera"/>
    <child link="head_camera_frame"/>
  </joint>
  <link name="camera_Link">
    <inertial>
      <origin xyz="-0.010760488460389 -0.00128395180189178 0.0201901124477915" rpy="0 0 0"/>
      <mass value="0.141237035309387"/>
      <inertia ixx="0.000273202627535233" ixy="-3.42245696528636E-06" ixz="-1.33953232133326E-08" iyy="3.08612840376037E-05" iyz="6.59073026004359E-07" izz="0.000259209165627936"/>
    </inertial>
    <visual>
      <origin xyz="0 0 0" rpy="0 0 0"/>
      <geometry>
        <mesh filename="package://robot_model/meshes/camera_Link.STL"/>
      </geometry>
      <material name="">
        <color rgba="0.752941176470588 0.752941176470588 0.752941176470588 1"/>
      </material>
    </visual>
    <collision>
      <origin xyz="0 0 0" rpy="0 0 0"/>
      <geometry>
        <mesh filename="package://robot_model/meshes/camera_Link.STL"/>
      </geometry>
    </collision>
  </link>
  <joint name="camera_joint" type="fixed">
    <origin xyz="0 0.52356 0.12606" rpy="0 -0.7854 -1.5708"/>
    <parent link="torso_1"/>
    <child link="camera_Link"/>
    <axis xyz="0 0 0"/>
  </joint>
  <link name="camera_link_frame"/>
  <joint name="camera_link_frame_joint" type="fixed">
    <origin xyz="0.02503 0.02375 0.02015" rpy="-1.5708 0 -1.5708"/>
    <parent link="camera_Link"/>
    <child link="camera_link_frame"/>
  </joint>
  <joint name="left_fixed" type="fixed">
    <parent link="torso_1"/>
    <child link="AR5-5_08L-W4C1C9-ZY2_base"/>
    <origin xyz="0.1047 0.52446 0" rpy="1.5708 3.1416 1.5708"/>
  </joint>
  <!--base-->
  <link name="AR5-5_08L-W4C1C9-ZY2_base">
    <visual>
      <geometry>
        <mesh filename="package://robot_model/meshes/AR5_P_L/AR5-5_08L-W4C1C9-ZY2_base.stl" scale="0.001 0.001 0.001"/>
      </geometry>
      <origin rpy="0 0 0" xyz="0.0 0.0 0.0"/>
      <material name="white"/>
    </visual>
    <collision>
      <geometry>
        <mesh filename="package://robot_model/meshes/AR5_P_L/AR5-5_08L-W4C1C9-ZY2_base.stl" scale="0.001 0.001 0.001"/>
      </geometry>
      <origin rpy="0 0 0" xyz="0.0 0.0 0.0"/>
    </collision>
  </link>
  <joint name="AR5-5_08L-W4C1C9-ZY2_joint_1" type="revolute">
    <parent link="AR5-5_08L-W4C1C9-ZY2_base"/>
    <child link="AR5-5_08L-W4C1C9-ZY2_link1"/>
    <limit effort="113" lower="-3.1067" upper="3.1067" velocity="3.0543261909900763"/>
    <axis xyz="0 0 1"/>
    <origin rpy="0 0 0" xyz="0.0 0.0 0.0"/>
  </joint>
  <!--link 1-->
  <link name="AR5-5_08L-W4C1C9-ZY2_link1">
    <visual>
      <geometry>
        <mesh filename="package://robot_model/meshes/AR5_P_L/AR5-5_08L-W4C1C9-ZY2_link1.stl" scale="0.001 0.001 0.001"/>
      </geometry>
      <origin rpy="0 0 0" xyz="0 0 0"/>
      <material name="white"/>
    </visual>
    <inertial>
      <mass value="2.166"/>
      <inertia ixx="0.00332249" ixy="0.00000032" ixz="-0.00000048" iyy="0.00260904" iyz="-0.00001486" izz="0.00317691"/>
      <origin rpy="0 0 0" xyz="-0.000184 0.0015680000000000002 0.172804"/>
    </inertial>
    <collision>
      <geometry>
        <mesh filename="package://robot_model/meshes/AR5_P_L/AR5-5_08L-W4C1C9-ZY2_link1.stl" scale="0.001 0.001 0.001"/>
      </geometry>
      <origin rpy="0 0 0" xyz="0 0 0"/>
    </collision>
  </link>
  <joint name="AR5-5_08L-W4C1C9-ZY2_joint_2" type="revolute">
    <parent link="AR5-5_08L-W4C1C9-ZY2_link1"/>
    <child link="AR5-5_08L-W4C1C9-ZY2_link2"/>
    <limit effort="113" lower="-2.0944" upper="2.0944" velocity="3.0543261909900763"/>
    <axis xyz="0 1 0"/>
    <origin rpy="0 0 0" xyz="0.0 0.0 0.1745"/>
  </joint>
  <!--link 2-->
  <link name="AR5-5_08L-W4C1C9-ZY2_link2">
    <visual>
      <geometry>
        <mesh filename="package://robot_model/meshes/AR5_P_L/AR5-5_08L-W4C1C9-ZY2_link2.stl" scale="0.001 0.001 0.001"/>
      </geometry>
      <origin rpy="0 0 0" xyz="0 0 0.0"/>
      <material name="white"/>
    </visual>
    <inertial>
      <mass value="1.903"/>
      <inertia ixx="0.00779803" ixy="0.00000248" ixz="-0.00000226" iyy="0.00674819" iyz="-0.00049283" izz="0.00305507"/>
      <origin rpy="0 0 0" xyz="-1.7e-05 0.001795 0.10668899999999999"/>
    </inertial>
    <collision>
      <geometry>
        <mesh filename="package://robot_model/meshes/AR5_P_L/AR5-5_08L-W4C1C9-ZY2_link2.stl" scale="0.001 0.001 0.001"/>
      </geometry>
      <origin rpy="0 0 0" xyz="0 0 0.0"/>
    </collision>
  </link>
  <joint name="AR5-5_08L-W4C1C9-ZY2_joint_3" type="revolute">
    <parent link="AR5-5_08L-W4C1C9-ZY2_link2"/>
    <child link="AR5-5_08L-W4C1C9-ZY2_link3"/>
    <limit effort="70" lower="-3.1067" upper="3.1067" velocity="4.71238898038469"/>
    <axis xyz="0 0 1"/>
    <origin rpy="0 0 0" xyz="0.0 0.0 0.332"/>
  </joint>
  <!--link 3-->
  <link name="AR5-5_08L-W4C1C9-ZY2_link3">
    <visual>
      <geometry>
        <mesh filename="package://robot_model/meshes/AR5_P_L/AR5-5_08L-W4C1C9-ZY2_link3.stl" scale="0.001 0.001 0.001"/>
      </geometry>
      <origin rpy="0 0 0" xyz="0 0 0"/>
      <material name="white"/>
    </visual>
    <inertial>
      <mass value="1.845"/>
      <inertia ixx="0.00641285" ixy="0.00000909" ixz="0.00034765" iyy="0.00591595" iyz="-0.00002314" izz="0.00276583"/>
      <origin rpy="0 0 0" xyz="0.008227 -0.0012729999999999998 -0.020611"/>
    </inertial>
    <collision>
      <geometry>
        <mesh filename="package://robot_model/meshes/AR5_P_L/AR5-5_08L-W4C1C9-ZY2_link3.stl" scale="0.001 0.001 0.001"/>
      </geometry>
      <origin rpy="0 0 0" xyz="0 0 0"/>
    </collision>
  </link>
  <joint name="AR5-5_08L-W4C1C9-ZY2_joint_4" type="revolute">
    <parent link="AR5-5_08L-W4C1C9-ZY2_link3"/>
    <child link="AR5-5_08L-W4C1C9-ZY2_link4"/>
    <limit effort="70" lower="-1.0472" upper="2.5307" velocity="5.235987755982989"/>
    <!--     lower="-1.0472" upper="1.0472" -->
    <axis xyz="0 1 0"/>
    <!--     <origin rpy="0 0 0" xyz=0.0105 0.0 0.0/> -->
    <origin rpy="0 0 0" xyz="0.0105 0.0 0.0"/>
  </joint>
  <!--link 4-->
  <link name="AR5-5_08L-W4C1C9-ZY2_link4">
    <visual>
      <geometry>
        <mesh filename="package://robot_model/meshes/AR5_P_L/AR5-5_08L-W4C1C9-ZY2_link4.stl" scale=".001 0.001 0.001"/>
      </geometry>
      <origin rpy="0 0 0" xyz="0.0 0.0 0.0"/>
      <material name="white"/>
    </visual>
    <inertial>
      <mass value="1.037"/>
      <inertia ixx="0.00294639" ixy="-0.00002418" ixz="-0.00012203" iyy="0.00244447" iyz="0.00022029" izz="0.00140961"/>
      <origin rpy="0 0 0" xyz="-0.009242 -0.0021720000000000003 0.084042"/>
    </inertial>
    <collision>
      <geometry>
        <mesh filename="package://robot_model/meshes/AR5_P_L/AR5-5_08L-W4C1C9-ZY2_link4.stl" scale="0.001 0.001 0.001"/>
      </geometry>
      <origin rpy="0 0 0" xyz="0.0 0.0 0.0"/>
    </collision>
  </link>
  <joint name="AR5-5_08L-W4C1C9-ZY2_joint_5" type="revolute">
    <parent link="AR5-5_08L-W4C1C9-ZY2_link4"/>
    <child link="AR5-5_08L-W4C1C9-ZY2_link5"/>
    <limit effort="19" lower="-3.1067" upper="3.1067" velocity="4.1887902047863905"/>
    <axis xyz="0 0 1"/>
    <origin rpy="0 0 0" xyz="-0.0105 0.0 0.278"/>
  </joint>
  <!--link 5-->
  <link name="AR5-5_08L-W4C1C9-ZY2_link5">
    <visual>
      <geometry>
        <mesh filename="package://robot_model/meshes/AR5_P_L/AR5-5_08L-W4C1C9-ZY2_link5.stl" scale="0.001 0.001 0.001"/>
      </geometry>
      <origin rpy="0 0 0" xyz="0 0 0"/>
      <material name="white"/>
    </visual>
    <inertial>
      <mass value="1.279"/>
      <inertia ixx="0.00241349" ixy="-0.00003807" ixz="-0.00004536" iyy="0.00200246" iyz="0.00006623" izz="0.00158693"/>
      <origin rpy="0 0 0" xyz="-0.000756 0.000723 -0.086764"/>
    </inertial>
    <collision>
      <geometry>
        <mesh filename="package://robot_model/meshes/AR5_P_L/AR5-5_08L-W4C1C9-ZY2_link5.stl" scale="0.001 0.001 0.001"/>
      </geometry>
      <origin rpy="0 0 0" xyz="0 0 0"/>
    </collision>
  </link>
  <joint name="AR5-5_08L-W4C1C9-ZY2_joint_6" type="revolute">
    <parent link="AR5-5_08L-W4C1C9-ZY2_link5"/>
    <child link="AR5-5_08L-W4C1C9-ZY2_link6"/>
    <limit effort="19" lower="-1.0472" upper="1.0472" velocity="4.1887902047863905"/>
    <axis xyz="0 1 0"/>
    <origin rpy="0.0 0.0 0" xyz="0.0 0.0 0.0"/>
  </joint>
  <!--link 6-->
  <link name="AR5-5_08L-W4C1C9-ZY2_link6">
    <visual>
      <geometry>
        <mesh filename="package://robot_model/meshes/AR5_P_L/AR5-5_08L-W4C1C9-ZY2_link6.stl" scale="0.001 0.001 0.001"/>
      </geometry>
      <origin rpy="0 0 0" xyz="0 0 0"/>
      <material name="white"/>
    </visual>
    <inertial>
      <mass value="0.906"/>
      <inertia ixx="0.00061429" ixy="-0.00000088" ixz="0.00000104" iyy="0.00074781" iyz="-0.00000047" izz="0.00075897"/>
      <origin rpy="0 0 0" xyz="-0.005104 0.000251 5.6e-05"/>
    </inertial>
    <collision>
      <geometry>
        <mesh filename="package://robot_model/meshes/AR5_P_L/AR5-5_08L-W4C1C9-ZY2_link6.stl" scale="0.001 0.001 0.001"/>
      </geometry>
      <origin rpy="0 0 0" xyz="0 0 0"/>
    </collision>
  </link>
  <joint name="AR5-5_08L-W4C1C9-ZY2_joint_7" type="revolute">
    <parent link="AR5-5_08L-W4C1C9-ZY2_link6"/>
    <child link="AR5-5_08L-W4C1C9-ZY2_link7"/>
    <limit effort="19" lower="-1.0472" upper="1.0472" velocity="4.1887902047863905"/>
    <axis xyz="1 0 0"/>
    <origin rpy="0.0 0.0 0" xyz="0.0 0.0 0.0"/>
  </joint>
  <!--link 7-->
  <link name="AR5-5_08L-W4C1C9-ZY2_link7">
    <visual>
      <geometry>
        <mesh filename="package://robot_model/meshes/AR5_P_L/AR5-5_08L-W4C1C9-ZY2_link7.stl" scale="0.001 0.001 0.001"/>
      </geometry>
      <origin rpy="0 0 0" xyz="0.0 0.0 0.0"/>
      <material name="white"/>
    </visual>
    <inertial>
      <mass value="0.33"/>
      <inertia ixx="0.00046062" ixy="0.00000269" ixz="0.00003859" iyy="0.00068652" iyz="-0.00000095" izz="0.00043943"/>
      <origin rpy="0 0 0" xyz="-0.001562 -0.000366 0.05392"/>
    </inertial>
    <collision>
      <geometry>
        <mesh filename="package://robot_model/meshes/AR5_P_L/AR5-5_08L-W4C1C9-ZY2_link7.stl" scale="0.001 0.001 0.001"/>
      </geometry>
      <origin rpy="0 0 0" xyz="0.0 0.0 0.0"/>
    </collision>
  </link>
  <link name="AR5-5_08L-W4C1C9-ZY2_flan_link">
    <inertial>
      <origin rpy="0 0 0" xyz="0 0 0"/>
      <mass value="0"/>
      <inertia ixx="0" ixy="0" ixz="0" iyy="0" iyz="0" izz="0"/>
    </inertial>
  </link>
  <joint name="AR5-5_08L-W4C1C9-ZY2_flan_joint" type="fixed">
    <parent link="AR5-5_08L-W4C1C9-ZY2_link7"/>
    <child link="AR5-5_08L-W4C1C9-ZY2_flan_link"/>
    <origin rpy="0 0 0" xyz="0 0 0.09"/>
  </joint>
  <joint name="gripper_plateL_joint" type="fixed">
    <parent link="AR5-5_08L-W4C1C9-ZY2_flan_link"/>
    <child link="gripper_plateL_link"/>
    <origin rpy="0 0 0" xyz="0 0 0"/>
  </joint>
  <link name="gripper_plateL_link">
    <visual>
      <origin rpy="1.5708 0 0" xyz="0.00955 0 0.07045"/>
      <geometry>
        <mesh filename="package://robot_model/meshes/gripper_plateL.stl" scale="0.001 0.001 0.001"/>
      </geometry>
      <material name="white"/>
    </visual>
    <collision>
      <origin rpy="1.5708 0 0" xyz="0.00955 0 0.07045"/>
      <geometry>
        <mesh filename="package://robot_model/meshes/gripper_plateL.stl" scale="0.001 0.001 0.001"/>
      </geometry>
    </collision>
  </link>
  <joint name="right_fixed" type="fixed">
    <parent link="torso_1"/>
    <child link="AR5-5_08R-W4C1C9-ZY2_base"/>
    <origin xyz="-0.1055 0.52456 0" rpy="1.5708 0 -1.5708"/>
  </joint>
  <!--base-->
  <link name="AR5-5_08R-W4C1C9-ZY2_base">
    <visual>
      <geometry>
        <mesh filename="package://robot_model/meshes/AR5_P_R/AR5-5_08R-W4C1C9-ZY2_base.stl" scale="0.001 0.001 0.001"/>
      </geometry>
      <origin rpy="0 0 0" xyz="0.0 0.0 0.0"/>
      <material name="white"/>
    </visual>
    <collision>
      <geometry>
        <mesh filename="package://robot_model/meshes/AR5_P_R/AR5-5_08R-W4C1C9-ZY2_base.stl" scale="0.001 0.001 0.001"/>
      </geometry>
      <origin rpy="0 0 0" xyz="0.0 0.0 0.0"/>
    </collision>
  </link>
  <joint name="AR5-5_08R-W4C1C9-ZY2_joint_1" type="revolute">
    <parent link="AR5-5_08R-W4C1C9-ZY2_base"/>
    <child link="AR5-5_08R-W4C1C9-ZY2_link1"/>
    <limit effort="113" lower="-3.1067" upper="3.1067" velocity="3.0543261909900763"/>
    <axis xyz="0 0 1"/>
    <origin rpy="0 0 0" xyz="0.0 0.0 0.0"/>
  </joint>
  <!--link 1-->
  <link name="AR5-5_08R-W4C1C9-ZY2_link1">
    <visual>
      <geometry>
        <mesh filename="package://robot_model/meshes/AR5_P_R/AR5-5_08R-W4C1C9-ZY2_link1.stl" scale="0.001 0.001 0.001"/>
      </geometry>
      <origin rpy="0 0 0" xyz="0 0 0"/>
      <material name="white"/>
    </visual>
    <inertial>
      <mass value="2.166"/>
      <inertia ixx="0.00329374" ixy="0.00000029" ixz="0.00000048" iyy="0.00258807" iyz="0.00001496" izz="0.00314817"/>
      <origin rpy="0 0 0" xyz="0.000186 -0.0015429999999999999 0.172784"/>
    </inertial>
    <collision>
      <geometry>
        <mesh filename="package://robot_model/meshes/AR5_P_R/AR5-5_08R-W4C1C9-ZY2_link1.stl" scale="0.001 0.001 0.001"/>
      </geometry>
      <origin rpy="0 0 0" xyz="0 0 0"/>
    </collision>
  </link>
  <joint name="AR5-5_08R-W4C1C9-ZY2_joint_2" type="revolute">
    <parent link="AR5-5_08R-W4C1C9-ZY2_link1"/>
    <child link="AR5-5_08R-W4C1C9-ZY2_link2"/>
    <limit effort="113" lower="-2.0944" upper="2.0944" velocity="3.0543261909900763"/>
    <axis xyz="0 1 0"/>
    <origin rpy="0 0 0" xyz="0.0 0.0 0.1745"/>
  </joint>
  <!--link 2-->
  <link name="AR5-5_08R-W4C1C9-ZY2_link2">
    <visual>
      <geometry>
        <mesh filename="package://robot_model/meshes/AR5_P_R/AR5-5_08R-W4C1C9-ZY2_link2.stl" scale="0.001 0.001 0.001"/>
      </geometry>
      <origin rpy="0 0 0" xyz="0 0 0.0"/>
      <material name="white"/>
    </visual>
    <inertial>
      <mass value="1.903"/>
      <inertia ixx="0.00779827" ixy="0.00000248" ixz="0.00000226" iyy="0.00674843" iyz="0.00049284" izz="0.00305518"/>
      <origin rpy="0 0 0" xyz="1.7e-05 -0.001795 0.10669100000000001"/>
    </inertial>
    <collision>
      <geometry>
        <mesh filename="package://robot_model/meshes/AR5_P_R/AR5-5_08R-W4C1C9-ZY2_link2.stl" scale="0.001 0.001 0.001"/>
      </geometry>
      <origin rpy="0 0 0" xyz="0 0 0.0"/>
    </collision>
  </link>
  <joint name="AR5-5_08R-W4C1C9-ZY2_joint_3" type="revolute">
    <parent link="AR5-5_08R-W4C1C9-ZY2_link2"/>
    <child link="AR5-5_08R-W4C1C9-ZY2_link3"/>
    <limit effort="70" lower="-3.1067" upper="3.1067" velocity="4.71238898038469"/>
    <axis xyz="0 0 1"/>
    <origin rpy="0 0 0" xyz="0.0 0.0 0.332"/>
  </joint>
  <!--link 3-->
  <link name="AR5-5_08R-W4C1C9-ZY2_link3">
    <visual>
      <geometry>
        <mesh filename="package://robot_model/meshes/AR5_P_R/AR5-5_08R-W4C1C9-ZY2_link3.stl" scale="0.001 0.001 0.001"/>
      </geometry>
      <origin rpy="0 0 0" xyz="0 0 0"/>
      <material name="white"/>
    </visual>
    <inertial>
      <mass value="1.845"/>
      <inertia ixx="0.00635592" ixy="0.00001599" ixz="0.00029945" iyy="0.00581609" iyz="0.00004683" izz="0.00269115"/>
      <origin rpy="0 0 0" xyz="0.009022 0.0009 -0.019936"/>
    </inertial>
    <collision>
      <geometry>
        <mesh filename="package://robot_model/meshes/AR5_P_R/AR5-5_08R-W4C1C9-ZY2_link3.stl" scale="0.001 0.001 0.001"/>
      </geometry>
      <origin rpy="0 0 0" xyz="0 0 0"/>
    </collision>
  </link>
  <joint name="AR5-5_08R-W4C1C9-ZY2_joint_4" type="revolute">
    <parent link="AR5-5_08R-W4C1C9-ZY2_link3"/>
    <child link="AR5-5_08R-W4C1C9-ZY2_link4"/>
    <limit effort="70" lower="-1.0472" upper="2.5307" velocity="5.235987755982989"/>
    <!--     lower="-1.0472" upper="1.0472" -->
    <axis xyz="0 1 0"/>
    <!--     <origin rpy="0 0 0" xyz=0.0105 0.0 0.0/> -->
    <origin rpy="0 0 0" xyz="0.0105 0.0 0.0"/>
  </joint>
  <!--link 4-->
  <link name="AR5-5_08R-W4C1C9-ZY2_link4">
    <visual>
      <geometry>
        <mesh filename="package://robot_model/meshes/AR5_P_R/AR5-5_08R-W4C1C9-ZY2_link4.stl" scale=".001 0.001 0.001"/>
      </geometry>
      <origin rpy="0 0 0" xyz="0.0 0.0 0.0"/>
      <material name="white"/>
    </visual>
    <inertial>
      <mass value="1.037"/>
      <inertia ixx="0.00294610" ixy="0.00002481" ixz="-0.00011850" iyy="0.00244455" iyz="-0.00022011" izz="0.00140934"/>
      <origin rpy="0 0 0" xyz="-0.009272 0.002169 0.084042"/>
    </inertial>
    <collision>
      <geometry>
        <mesh filename="package://robot_model/meshes/AR5_P_R/AR5-5_08R-W4C1C9-ZY2_link4.stl" scale="0.001 0.001 0.001"/>
      </geometry>
      <origin rpy="0 0 0" xyz="0.0 0.0 0.0"/>
    </collision>
  </link>
  <joint name="AR5-5_08R-W4C1C9-ZY2_joint_5" type="revolute">
    <parent link="AR5-5_08R-W4C1C9-ZY2_link4"/>
    <child link="AR5-5_08R-W4C1C9-ZY2_link5"/>
    <limit effort="19" lower="-3.1067" upper="3.1067" velocity="4.1887902047863905"/>
    <axis xyz="0 0 1"/>
    <origin rpy="0 0 0" xyz="-0.0105 0.0 0.278"/>
  </joint>
  <!--link 5-->
  <link name="AR5-5_08R-W4C1C9-ZY2_link5">
    <visual>
      <geometry>
        <mesh filename="package://robot_model/meshes/AR5_P_R/AR5-5_08R-W4C1C9-ZY2_link5.stl" scale="0.001 0.001 0.001"/>
      </geometry>
      <origin rpy="0 0 0" xyz="0 0 0"/>
      <material name="white"/>
    </visual>
    <inertial>
      <mass value="1.279"/>
      <inertia ixx="0.00240951" ixy="0.00004151" ixz="-0.00004311" iyy="0.00200115" iyz="-0.00006491" izz="0.00158266"/>
      <origin rpy="0 0 0" xyz="-0.000776 -0.000804 -0.08673399999999999"/>
    </inertial>
    <collision>
      <geometry>
        <mesh filename="package://robot_model/meshes/AR5_P_R/AR5-5_08R-W4C1C9-ZY2_link5.stl" scale="0.001 0.001 0.001"/>
      </geometry>
      <origin rpy="0 0 0" xyz="0 0 0"/>
    </collision>
  </link>
  <joint name="AR5-5_08R-W4C1C9-ZY2_joint_6" type="revolute">
    <parent link="AR5-5_08R-W4C1C9-ZY2_link5"/>
    <child link="AR5-5_08R-W4C1C9-ZY2_link6"/>
    <limit effort="19" lower="-1.0472" upper="1.0472" velocity="4.1887902047863905"/>
    <axis xyz="0 1 0"/>
    <origin rpy="0.0 0.0 0" xyz="0.0 0.0 0.0"/>
  </joint>
  <!--link 6-->
  <link name="AR5-5_08R-W4C1C9-ZY2_link6">
    <visual>
      <geometry>
        <mesh filename="package://robot_model/meshes/AR5_P_R/AR5-5_08R-W4C1C9-ZY2_link6.stl" scale="0.001 0.001 0.001"/>
      </geometry>
      <origin rpy="0 0 0" xyz="0 0 0"/>
      <material name="white"/>
    </visual>
    <inertial>
      <mass value="0.906"/>
      <inertia ixx="0.00061487" ixy="0.00000092" ixz="-0.00000097" iyy="0.00074943" iyz="-0.00000047" izz="0.00076056"/>
      <origin rpy="0 0 0" xyz="-0.005059 -0.00025 -5.5e-05"/>
    </inertial>
    <collision>
      <geometry>
        <mesh filename="package://robot_model/meshes/AR5_P_R/AR5-5_08R-W4C1C9-ZY2_link6.stl" scale="0.001 0.001 0.001"/>
      </geometry>
      <origin rpy="0 0 0" xyz="0 0 0"/>
    </collision>
  </link>
  <joint name="AR5-5_08R-W4C1C9-ZY2_joint_7" type="revolute">
    <parent link="AR5-5_08R-W4C1C9-ZY2_link6"/>
    <child link="AR5-5_08R-W4C1C9-ZY2_link7"/>
    <limit effort="19" lower="-1.0472" upper="1.0472" velocity="4.1887902047863905"/>
    <axis xyz="1 0 0"/>
    <origin rpy="0.0 0.0 0" xyz="0.0 0.0 0.0"/>
  </joint>
  <!--link 7-->
  <link name="AR5-5_08R-W4C1C9-ZY2_link7">
    <visual>
      <geometry>
        <mesh filename="package://robot_model/meshes/AR5_P_R/AR5-5_08R-W4C1C9-ZY2_link7.stl" scale="0.001 0.001 0.001"/>
      </geometry>
      <origin rpy="0 0 0" xyz="0.0 0.0 0.0"/>
      <material name="white"/>
    </visual>
    <inertial>
      <mass value="0.33"/>
      <inertia ixx="0.00046020" ixy="-0.00000266" ixz="0.00004064" iyy="0.00068698" iyz="0.00000424" izz="0.00043963"/>
      <origin rpy="0 0 0" xyz="-0.00122 0.0006730000000000001 0.053984000000000004"/>
    </inertial>
    <collision>
      <geometry>
        <mesh filename="package://robot_model/meshes/AR5_P_R/AR5-5_08R-W4C1C9-ZY2_link7.stl" scale="0.001 0.001 0.001"/>
      </geometry>
      <origin rpy="0 0 0" xyz="0.0 0.0 0.0"/>
    </collision>
  </link>
  <link name="AR5-5_08R-W4C1C9-ZY2_flan_link">
    <inertial>
      <origin rpy="0 0 0" xyz="0 0 0"/>
      <mass value="0"/>
      <inertia ixx="0" ixy="0" ixz="0" iyy="0" iyz="0" izz="0"/>
    </inertial>
  </link>
  <joint name="AR5-5_08R-W4C1C9-ZY2_flan_joint" type="fixed">
    <parent link="AR5-5_08R-W4C1C9-ZY2_link7"/>
    <child link="AR5-5_08R-W4C1C9-ZY2_flan_link"/>
    <origin rpy="0 0 0" xyz="0 0 0.09"/>
  </joint>
  <joint name="gripper_plateR_joint" type="fixed">
    <parent link="AR5-5_08R-W4C1C9-ZY2_flan_link"/>
    <child link="gripper_plateR_link"/>
    <origin rpy="0 0 0" xyz="0 0 0"/>
  </joint>
  <link name="gripper_plateR_link">
    <visual>
      <origin rpy="1.5708 0 0" xyz="0.00955 0 0.07045"/>
      <geometry>
        <mesh filename="package://robot_model/meshes/gripper_plateR.stl" scale="0.001 0.001 0.001"/>
      </geometry>
      <material name="white"/>
    </visual>
    <collision>
      <origin rpy="1.5708 0 0" xyz="0.00955 0 0.07045"/>
      <geometry>
        <mesh filename="package://robot_model/meshes/gripper_plateR.stl" scale="0.001 0.001 0.001"/>
      </geometry>
    </collision>
  </link>
  <joint name="AR5-5_08L-W4C1C9-ZY2_rh6_mount_joint" type="fixed">
    <parent link="gripper_plateL_link"/>
    <child link="rh6_left_base_link"/>
    <origin xyz="0 0 0.01025" rpy="0 0 0"/>
  </joint>
  <link name="rh6_left_base_link">
    <inertial>
      <origin xyz="-0.00261509912067082 -0.00202384901005411 0.0609899196930254" rpy="0 0 0"/>
      <mass value="0.144625530976132"/>
      <inertia ixx="0.000133309599124317" ixy="-1.82145713429529E-07" ixz="3.32894452619656E-06" iyy="8.49751509488818E-05" iyz="1.7292812695271E-06" izz="6.01735771930698E-05"/>
    </inertial>
    <visual>
      <origin xyz="0 0 0" rpy="0 0 0"/>
      <geometry>
        <mesh filename="package://robot_model/meshes/rh6_ctrl/base_linkz.STL"/>
      </geometry>
      <material name="">
        <color rgba="0.898039215686275 0.917647058823529 0.929411764705882 1"/>
      </material>
    </visual>
    <collision>
      <origin xyz="0 0 0" rpy="0 0 0"/>
      <geometry>
        <mesh filename="package://robot_model/meshes/rh6_ctrl/base_linkz.STL"/>
      </geometry>
    </collision>
  </link>
  <link name="rh6_left_fz11_Link">
    <inertial>
      <origin xyz="-0.00636137464373584 1.32504361038954E-07 0.00938049379418998" rpy="0 0 0"/>
      <mass value="0.0118860026879453"/>
      <inertia ixx="7.74702988388344E-07" ixy="9.44838007032962E-12" ixz="-1.45349151739363E-07" iyy="1.06344992792549E-06" iyz="7.07126022924055E-12" izz="1.01259075358287E-06"/>
    </inertial>
    <visual>
      <origin xyz="0 0 0" rpy="0 0 0"/>
      <geometry>
        <mesh filename="package://robot_model/meshes/rh6_ctrl/fz11_Link.STL"/>
      </geometry>
      <material name="">
        <color rgba="0.898039215686275 0.917647058823529 0.929411764705882 1"/>
      </material>
    </visual>
    <collision>
      <origin xyz="0 0 0" rpy="0 0 0"/>
      <geometry>
        <mesh filename="package://robot_model/meshes/rh6_ctrl/fz11_Link.STL"/>
      </geometry>
    </collision>
  </link>
  <joint name="rh6_left_fz11" type="revolute">
    <origin xyz="0.0135 -0.022 0.0398" rpy="0 0 1.5708"/>
    <parent link="rh6_left_base_link"/>
    <child link="rh6_left_fz11_Link"/>
    <axis xyz="0 0 1"/>
    <limit lower="0" upper="2.356" effort="0" velocity="0"/>
  </joint>
  <link name="rh6_left_fz12_Link">
    <inertial>
      <origin xyz="-0.0171306596068069 0.00371895991913085 4.99658495023425E-07" rpy="0 0 0"/>
      <mass value="0.0125497959689692"/>
      <inertia ixx="8.09093816336842E-07" ixy="5.16426686845547E-07" ixz="2.07629546130886E-10" iyy="2.83181034231341E-06" iyz="1.04480554936718E-11" izz="2.66845480195757E-06"/>
    </inertial>
    <visual>
      <origin xyz="0 0 0" rpy="0 0 0"/>
      <geometry>
        <mesh filename="package://robot_model/meshes/rh6_ctrl/fz12_Link.STL"/>
      </geometry>
      <material name="">
        <color rgba="0.898039215686275 0.917647058823529 0.929411764705882 1"/>
      </material>
    </visual>
    <collision>
      <origin xyz="0 0 0" rpy="0 0 0"/>
      <geometry>
        <mesh filename="package://robot_model/meshes/rh6_ctrl/fz12_Link.STL"/>
      </geometry>
    </collision>
  </link>
  <joint name="rh6_left_fz12" type="revolute">
    <origin xyz="-0.0105 0 0.0107" rpy="1.5708 0 0"/>
    <parent link="rh6_left_fz11_Link"/>
    <child link="rh6_left_fz12_Link"/>
    <axis xyz="0 0 -1"/>
    <limit lower="0" upper="0.698" effort="0" velocity="0"/>
  </joint>
  <link name="rh6_left_fz13_Link">
    <inertial>
      <origin xyz="-0.0158452246782004 0.00619313031274138 -5.24698446713323E-06" rpy="0 0 0"/>
      <mass value="0.00766844548693782"/>
      <inertia ixx="7.70926142561633E-07" ixy="6.47378725305476E-07" ixz="-6.26868773712833E-10" iyy="1.36028636261355E-06" iyz="3.0858883161577E-10" izz="1.6484807866159E-06"/>
    </inertial>
    <visual>
      <origin xyz="0 0 0" rpy="0 0 0"/>
      <geometry>
        <mesh filename="package://robot_model/meshes/rh6_ctrl/fz13_Link.STL"/>
      </geometry>
      <material name="">
        <color rgba="0.898039215686275 0.917647058823529 0.929411764705882 1"/>
      </material>
    </visual>
    <collision>
      <origin xyz="0 0 0" rpy="0 0 0"/>
      <geometry>
        <mesh filename="package://robot_model/meshes/rh6_ctrl/fz13_Link.STL"/>
      </geometry>
    </collision>
  </link>
  <joint name="rh6_left_fz13" type="revolute">
    <origin xyz="-0.040457 0.011223 0" rpy="0 0 0"/>
    <parent link="rh6_left_fz12_Link"/>
    <child link="rh6_left_fz13_Link"/>
    <axis xyz="0 0 -1"/>
    <limit lower="0" upper="1.169" effort="0" velocity="0"/>
  </joint>
  <link name="rh6_left_fz14_Link">
    <inertial>
      <origin xyz="6.84221826707798E-06 -0.00329677647235913 -0.0165004874842477" rpy="0 0 0"/>
      <mass value="0.00378673281389061"/>
      <inertia ixx="4.70044970140894E-07" ixy="-9.16610951761662E-13" ixz="9.80771601813381E-11" iyy="4.91875647343619E-07" iyz="-1.26714352849381E-07" izz="1.41742406291919E-07"/>
    </inertial>
    <visual>
      <origin xyz="0 0 0" rpy="0 0 0"/>
      <geometry>
        <mesh filename="package://robot_model/meshes/rh6_ctrl/fz14_Link.STL"/>
      </geometry>
      <material name="">
        <color rgba="0.298039215686275 0.298039215686275 0.298039215686275 1"/>
      </material>
    </visual>
    <collision>
      <origin xyz="0 0 0" rpy="0 0 0"/>
      <geometry>
        <mesh filename="package://robot_model/meshes/rh6_ctrl/fz14_Link.STL"/>
      </geometry>
    </collision>
  </link>
  <joint name="rh6_left_fz14" type="revolute">
    <origin xyz="-0.036284 0.0268 0" rpy="-0.3665 -1.5708 0"/>
    <parent link="rh6_left_fz13_Link"/>
    <child link="rh6_left_fz14_Link"/>
    <axis xyz="0 0 -1"/>
    <limit lower="0" upper="0" effort="0" velocity="0"/>
  </joint>
  <link name="rh6_left_fz21_Link">
    <inertial>
      <origin xyz="-0.0183100214086785 -0.00110403770235035 1.45621593276163E-06" rpy="0 0 0"/>
      <mass value="0.0100639388101722"/>
      <inertia ixx="4.62549859534186E-07" ixy="-1.43110207723793E-07" ixz="2.05628850227063E-10" iyy="2.22041832229495E-06" iyz="7.63349863278686E-11" izz="2.08162821109976E-06"/>
    </inertial>
    <visual>
      <origin xyz="0 0 0" rpy="0 0 0"/>
      <geometry>
        <mesh filename="package://robot_model/meshes/rh6_ctrl/fz21_Link.STL"/>
      </geometry>
      <material name="">
        <color rgba="0.898039215686275 0.917647058823529 0.929411764705882 1"/>
      </material>
    </visual>
    <collision>
      <origin xyz="0 0 0" rpy="0 0 0"/>
      <geometry>
        <mesh filename="package://robot_model/meshes/rh6_ctrl/fz21_Link.STL"/>
      </geometry>
    </collision>
  </link>
  <joint name="rh6_left_fz21" type="revolute">
    <origin xyz="-0.0035 -0.029833 0.11095" rpy="3.1416 1.4923 1.5708"/>
    <parent link="rh6_left_base_link"/>
    <child link="rh6_left_fz21_Link"/>
    <axis xyz="0 0 -1"/>
    <limit lower="0" upper="1.518" effort="0" velocity="0"/>
  </joint>
  <link name="rh6_left_fz22_Link">
    <inertial>
      <origin xyz="-0.0162663890924856 -0.00032857563536115 7.63729580743888E-07" rpy="0 0 0"/>
      <mass value="0.00358588124079119"/>
      <inertia ixx="1.44429040318132E-07" ixy="1.05993289352036E-07" ixz="-2.72822254662679E-11" iyy="7.23455267802395E-07" iyz="3.04879521204743E-11" izz="7.27926306560542E-07"/>
    </inertial>
    <visual>
      <origin xyz="0 0 0" rpy="0 0 0"/>
      <geometry>
        <mesh filename="package://robot_model/meshes/rh6_ctrl/fz22_Link.STL"/>
      </geometry>
      <material name="">
        <color rgba="0.658823529411765 0.619607843137255 0.56078431372549 1"/>
      </material>
    </visual>
    <collision>
      <origin xyz="0 0 0" rpy="0 0 0"/>
      <geometry>
        <mesh filename="package://robot_model/meshes/rh6_ctrl/fz22_Link.STL"/>
      </geometry>
    </collision>
  </link>
  <joint name="rh6_left_fz22" type="revolute">
    <origin xyz="-0.0419 -0.001 0" rpy="0 0 0"/>
    <parent link="rh6_left_fz21_Link"/>
    <child link="rh6_left_fz22_Link"/>
    <axis xyz="0 0 -1"/>
    <limit lower="0" upper="1.623" effort="0" velocity="0"/>
  </joint>
  <link name="rh6_left_fz23_Link">
    <inertial>
      <origin xyz="5.01939634914121E-06 0.00358041979242141 -0.0177336235160931" rpy="0 0 0"/>
      <mass value="0.00260328499217126"/>
      <inertia ixx="3.22603614487991E-07" ixy="-6.28873843071622E-12" ixz="9.57453494543153E-11" iyy="3.1137947502367E-07" iyz="9.01377966391627E-08" izz="7.26739486599914E-08"/>
    </inertial>
    <visual>
      <origin xyz="0 0 0" rpy="0 0 0"/>
      <geometry>
        <mesh filename="package://robot_model/meshes/rh6_ctrl/fz23_Link.STL"/>
      </geometry>
      <material name="">
        <color rgba="0.298039215686275 0.298039215686275 0.298039215686275 1"/>
      </material>
    </visual>
    <collision>
      <origin xyz="0 0 0" rpy="0 0 0"/>
      <geometry>
        <mesh filename="package://robot_model/meshes/rh6_ctrl/fz23_Link.STL"/>
      </geometry>
    </collision>
  </link>
  <joint name="rh6_left_fz23" type="revolute">
    <origin xyz="-0.043692 0.011217 0" rpy="1.5708 1.5695 -1.5543"/>
    <parent link="rh6_left_fz22_Link"/>
    <child link="rh6_left_fz23_Link"/>
    <axis xyz="0 0 -1"/>
    <limit lower="0" upper="0" effort="0" velocity="0"/>
  </joint>
  <link name="rh6_left_fz31_Link">
    <inertial>
      <origin xyz="-0.0233372043143448 -0.000590478503409209 1.04886742833708E-06" rpy="0 0 0"/>
      <mass value="0.00829865788114667"/>
      <inertia ixx="3.67197735996417E-07" ixy="-1.18936164176857E-07" ixz="1.55843724157167E-10" iyy="2.3734329678931E-06" iyz="3.77450724437793E-11" izz="2.26081374668809E-06"/>
    </inertial>
    <visual>
      <origin xyz="0 0 0" rpy="0 0 0"/>
      <geometry>
        <mesh filename="package://robot_model/meshes/rh6_ctrl/fz31_Link.STL"/>
      </geometry>
      <material name="">
        <color rgba="0.898039215686275 0.917647058823529 0.929411764705882 1"/>
      </material>
    </visual>
    <collision>
      <origin xyz="0 0 0" rpy="0 0 0"/>
      <geometry>
        <mesh filename="package://robot_model/meshes/rh6_ctrl/fz31_Link.STL"/>
      </geometry>
    </collision>
  </link>
  <joint name="rh6_left_fz31" type="revolute">
    <origin xyz="-0.0035 -0.009945 0.112" rpy="3.1416 1.5446 1.5708"/>
    <parent link="rh6_left_base_link"/>
    <child link="rh6_left_fz31_Link"/>
    <axis xyz="0 0 -1"/>
    <limit lower="0" upper="1.571" effort="0" velocity="0"/>
  </joint>
  <link name="rh6_left_fz32_Link">
    <inertial>
      <origin xyz="-0.016267707795044 -0.000256548647881605 7.09501456184949E-07" rpy="0 0 0"/>
      <mass value="0.00358589458230619"/>
      <inertia ixx="1.45377941149196E-07" ixy="1.08551160226217E-07" ixz="-3.05507403832043E-11" iyy="7.22506767907826E-07" iyz="3.07132553302964E-11" izz="7.27926863638964E-07"/>
    </inertial>
    <visual>
      <origin xyz="0 0 0" rpy="0 0 0"/>
      <geometry>
        <mesh filename="package://robot_model/meshes/rh6_ctrl/fz32_Link.STL"/>
      </geometry>
      <material name="">
        <color rgba="0.658823529411765 0.619607843137255 0.56078431372549 1"/>
      </material>
    </visual>
    <collision>
      <origin xyz="0 0 0" rpy="0 0 0"/>
      <geometry>
        <mesh filename="package://robot_model/meshes/rh6_ctrl/fz32_Link.STL"/>
      </geometry>
    </collision>
  </link>
  <joint name="rh6_left_fz32" type="revolute">
    <origin xyz="-0.0519 -0.001 0" rpy="0 0 0"/>
    <parent link="rh6_left_fz31_Link"/>
    <child link="rh6_left_fz32_Link"/>
    <axis xyz="0 0 -1"/>
    <limit lower="0" upper="1.641" effort="0" velocity="0"/>
  </joint>
  <link name="rh6_left_fz33_Link">
    <inertial>
      <origin xyz="1.37260992284912E-06 0.0035803233705618 -0.0177332743500691" rpy="0 0 0"/>
      <mass value="0.00260331177753113"/>
      <inertia ixx="3.22618051421039E-07" ixy="3.25713153352679E-12" ixz="9.69403513262157E-12" iyy="3.11391716342147E-07" iyz="9.01418764699119E-08" izz="7.26739552705994E-08"/>
    </inertial>
    <visual>
      <origin xyz="0 0 0" rpy="0 0 0"/>
      <geometry>
        <mesh filename="package://robot_model/meshes/rh6_ctrl/fz33_Link.STL"/>
      </geometry>
      <material name="">
        <color rgba="0.298039215686275 0.298039215686275 0.298039215686275 1"/>
      </material>
    </visual>
    <collision>
      <origin xyz="0 0 0" rpy="0 0 0"/>
      <geometry>
        <mesh filename="package://robot_model/meshes/rh6_ctrl/fz33_Link.STL"/>
      </geometry>
    </collision>
  </link>
  <joint name="rh6_left_fz33" type="revolute">
    <origin xyz="-0.043641 0.01141 0" rpy="1.5708 1.5705 -1.5587"/>
    <parent link="rh6_left_fz32_Link"/>
    <child link="rh6_left_fz33_Link"/>
    <axis xyz="0 0 -1"/>
    <limit lower="0" upper="0" effort="0" velocity="0"/>
  </joint>
  <link name="rh6_left_fz41_Link">
    <inertial>
      <origin xyz="-0.0183100239662456 -0.00110404357001215 1.44449168429719E-06" rpy="0 0 0"/>
      <mass value="0.0100639395246075"/>
      <inertia ixx="4.62549923176114E-07" ixy="-1.43110791933657E-07" ixz="2.04440787125584E-10" iyy="2.22041842134978E-06" iyz="7.50863566540316E-11" izz="2.0816291905166E-06"/>
    </inertial>
    <visual>
      <origin xyz="0 0 0" rpy="0 0 0"/>
      <geometry>
        <mesh filename="package://robot_model/meshes/rh6_ctrl/fz41_Link.STL"/>
      </geometry>
      <material name="">
        <color rgba="0.898039215686275 0.917647058823529 0.929411764705882 1"/>
      </material>
    </visual>
    <collision>
      <origin xyz="0 0 0" rpy="0 0 0"/>
      <geometry>
        <mesh filename="package://robot_model/meshes/rh6_ctrl/fz41_Link.STL"/>
      </geometry>
    </collision>
  </link>
  <joint name="rh6_left_fz41" type="revolute">
    <origin xyz="-0.0035 0.009945 0.11099" rpy="0 1.5446 -1.5708"/>
    <parent link="rh6_left_base_link"/>
    <child link="rh6_left_fz41_Link"/>
    <axis xyz="0 0 -1"/>
    <limit lower="0" upper="1.571" effort="0" velocity="0"/>
  </joint>
  <link name="rh6_left_fz42_Link">
    <inertial>
      <origin xyz="-0.0162670020037646 -0.000328352735815995 3.07883416161142E-07" rpy="0 0 0"/>
      <mass value="0.00358604216233826"/>
      <inertia ixx="1.44429145926852E-07" ixy="1.06000284346228E-07" ixz="-4.96653342664326E-11" iyy="7.23505035419092E-07" iyz="2.38944350125517E-11" izz="7.2797707549858E-07"/>
    </inertial>
    <visual>
      <origin xyz="0 0 0" rpy="0 0 0"/>
      <geometry>
        <mesh filename="package://robot_model/meshes/rh6_ctrl/fz42_Link.STL"/>
      </geometry>
      <material name="">
        <color rgba="0.658823529411765 0.619607843137255 0.56078431372549 1"/>
      </material>
    </visual>
    <collision>
      <origin xyz="0 0 0" rpy="0 0 0"/>
      <geometry>
        <mesh filename="package://robot_model/meshes/rh6_ctrl/fz42_Link.STL"/>
      </geometry>
    </collision>
  </link>
  <joint name="rh6_left_fz42" type="revolute">
    <origin xyz="-0.0419 -0.001 0" rpy="0 0 0"/>
    <parent link="rh6_left_fz41_Link"/>
    <child link="rh6_left_fz42_Link"/>
    <axis xyz="0 0 -1"/>
    <limit lower="0" upper="1.658" effort="0" velocity="0"/>
  </joint>
  <link name="rh6_left_fz43_Link">
    <inertial>
      <origin xyz="-1.80939820419376E-06 0.0035802583127047 -0.0177330843414484" rpy="0 0 0"/>
      <mass value="0.00260328927031042"/>
      <inertia ixx="3.22619446745819E-07" ixy="5.22933144242645E-12" ixz="-4.37845727909771E-11" iyy="3.11392771355379E-07" iyz="9.01416934497917E-08" izz="7.26723312106009E-08"/>
    </inertial>
    <visual>
      <origin xyz="0 0 0" rpy="0 0 0"/>
      <geometry>
        <mesh filename="package://robot_model/meshes/rh6_ctrl/fz43_Link.STL"/>
      </geometry>
      <material name="">
        <color rgba="0.298039215686275 0.298039215686275 0.298039215686275 1"/>
      </material>
    </visual>
    <collision>
      <origin xyz="0 0 0" rpy="0 0 0"/>
      <geometry>
        <mesh filename="package://robot_model/meshes/rh6_ctrl/fz43_Link.STL"/>
      </geometry>
    </collision>
  </link>
  <joint name="rh6_left_fz43" type="revolute">
    <origin xyz="-0.043692 0.011217 0" rpy="-1.5708 1.5704 1.5873"/>
    <parent link="rh6_left_fz42_Link"/>
    <child link="rh6_left_fz43_Link"/>
    <axis xyz="0 0 -1"/>
    <limit lower="0" upper="0" effort="0" velocity="0"/>
  </joint>
  <link name="rh6_left_fz51_Link">
    <inertial>
      <origin xyz="-0.0158684817906832 -0.00100262396836537 1.32847910480627E-06" rpy="0 0 0"/>
      <mass value="0.00870573006547253"/>
      <inertia ixx="3.93124077531552E-07" ixy="-1.16969518921071E-07" ixz="1.46116447151274E-10" iyy="1.63160381847551E-06" iyz="5.89909384492466E-11" izz="1.50797999524283E-06"/>
    </inertial>
    <visual>
      <origin xyz="0 0 0" rpy="0 0 0"/>
      <geometry>
        <mesh filename="package://robot_model/meshes/rh6_ctrl/fz51_Link.STL"/>
      </geometry>
      <material name="">
        <color rgba="0.898039215686275 0.917647058823529 0.929411764705882 1"/>
      </material>
    </visual>
    <collision>
      <origin xyz="0 0 0" rpy="0 0 0"/>
      <geometry>
        <mesh filename="package://robot_model/meshes/rh6_ctrl/fz51_Link.STL"/>
      </geometry>
    </collision>
  </link>
  <joint name="rh6_left_fz51" type="revolute">
    <origin xyz="-0.0035 0.029624 0.10795" rpy="0 1.4923 -1.5708"/>
    <parent link="rh6_left_base_link"/>
    <child link="rh6_left_fz51_Link"/>
    <axis xyz="0 0 -1"/>
    <limit lower="0" upper="1.545" effort="0" velocity="0"/>
  </joint>
  <link name="rh6_left_fz52_Link">
    <inertial>
      <origin xyz="-0.0162670718963009 -0.000328217017429799 2.67080852364709E-07" rpy="0 0 0"/>
      <mass value="0.00358606108430071"/>
      <inertia ixx="1.44430667118152E-07" ixy="1.06005742555026E-07" ixz="-5.31901274841338E-11" iyy="7.23506245846155E-07" iyz="2.3839216263499E-11" izz="7.279802802298E-07"/>
    </inertial>
    <visual>
      <origin xyz="0 0 0" rpy="0 0 0"/>
      <geometry>
        <mesh filename="package://robot_model/meshes/rh6_ctrl/fz52_Link.STL"/>
      </geometry>
      <material name="">
        <color rgba="0.658823529411765 0.619607843137255 0.56078431372549 1"/>
      </material>
    </visual>
    <collision>
      <origin xyz="0 0 0" rpy="0 0 0"/>
      <geometry>
        <mesh filename="package://robot_model/meshes/rh6_ctrl/fz52_Link.STL"/>
      </geometry>
    </collision>
  </link>
  <joint name="rh6_left_fz52" type="revolute">
    <origin xyz="-0.0369 -0.001 0" rpy="0 0 0"/>
    <parent link="rh6_left_fz51_Link"/>
    <child link="rh6_left_fz52_Link"/>
    <axis xyz="0 0 -1"/>
    <limit lower="0" upper="1.658" effort="0" velocity="0"/>
  </joint>
  <link name="rh6_left_fz53_Link">
    <inertial>
      <origin xyz="-5.01630269825887E-06 0.00358024546548252 -0.0177330754396588" rpy="0 0 0"/>
      <mass value="0.00260328329004836"/>
      <inertia ixx="3.22616272404965E-07" ixy="1.35246112705223E-11" ixz="-1.19647172462991E-10" iyy="3.11389657789929E-07" iyz="9.01411448719963E-08" izz="7.26723107121053E-08"/>
    </inertial>
    <visual>
      <origin xyz="0 0 0" rpy="0 0 0"/>
      <geometry>
        <mesh filename="package://robot_model/meshes/rh6_ctrl/fz53_Link.STL"/>
      </geometry>
      <material name="">
        <color rgba="0.298039215686275 0.298039215686275 0.298039215686275 1"/>
      </material>
    </visual>
    <collision>
      <origin xyz="0 0 0" rpy="0 0 0"/>
      <geometry>
        <mesh filename="package://robot_model/meshes/rh6_ctrl/fz53_Link.STL"/>
      </geometry>
    </collision>
  </link>
  <joint name="rh6_left_fz53" type="revolute">
    <origin xyz="-0.043691 0.011217 0" rpy="-1.5708 1.5695 1.5873"/>
    <parent link="rh6_left_fz52_Link"/>
    <child link="rh6_left_fz53_Link"/>
    <axis xyz="0 0 -1"/>
    <limit lower="0" upper="0" effort="0" velocity="0"/>
  </joint>
  <link name="rh6_left_grasp_center">
    <visual>
      <origin xyz="0 0 0" rpy="0 0 0"/>
      <geometry>
        <sphere radius="0.002"/>
      </geometry>
      <material name="grasp_center_green">
        <color rgba="0 1 0 1"/>
      </material>
    </visual>
  </link>
  <joint name="rh6_left_grasp_center_joint" type="fixed">
    <parent link="rh6_left_base_link"/>
    <child link="rh6_left_grasp_center"/>
    <origin xyz="0.02 0 0.1" rpy="0 0 0"/>
  </joint>
  <joint name="AR5-5_08R-W4C1C9-ZY2_rh6_mount_joint" type="fixed">
    <parent link="gripper_plateR_link"/>
    <child link="rh6_right_base_link"/>
    <origin xyz="0 0 0.01025" rpy="0 0 0"/>
  </joint>
  <link name="rh6_right_base_link">
    <inertial>
      <origin xyz="-0.00354104285456125 0.00204598885782099 0.0605396757269698" rpy="0 0 0"/>
      <mass value="0.211569079117232"/>
      <inertia ixx="0.000227960492976313" ixy="2.84392055686079E-07" ixz="5.26461841221454E-06" iyy="0.00014411212671873" iyz="-2.9868718911556E-06" izz="0.000100006031139727"/>
    </inertial>
    <visual>
      <origin xyz="0 0 0" rpy="0 0 0"/>
      <geometry>
        <mesh filename="package://robot_model/meshes/rh6_ctrl/base_linky.STL"/>
      </geometry>
      <material name="">
        <color rgba="0.898039215686275 0.917647058823529 0.929411764705882 1"/>
      </material>
    </visual>
    <collision>
      <origin xyz="0 0 0" rpy="0 0 0"/>
      <geometry>
        <mesh filename="package://robot_model/meshes/rh6_ctrl/base_linky.STL"/>
      </geometry>
    </collision>
  </link>
  <link name="rh6_right_fy11_Link">
    <inertial>
      <origin xyz="0.00679002520654505 -1.28183186065556E-07 0.00921783143572007" rpy="0 0 0"/>
      <mass value="0.0122865280263998"/>
      <inertia ixx="7.8328209014543E-07" ixy="9.44825770755344E-12" ixz="1.45349144840083E-07" iyy="1.06364945004909E-06" iyz="-7.07109523425218E-12" izz="1.02116982302802E-06"/>
    </inertial>
    <visual>
      <origin xyz="0 0 0" rpy="0 0 0"/>
      <geometry>
        <mesh filename="package://robot_model/meshes/rh6_ctrl/fy11_Link.STL"/>
      </geometry>
      <material name="">
        <color rgba="0.898039215686275 0.917647058823529 0.929411764705882 1"/>
      </material>
    </visual>
    <collision>
      <origin xyz="0 0 0" rpy="0 0 0"/>
      <geometry>
        <mesh filename="package://robot_model/meshes/rh6_ctrl/fy11_Link.STL"/>
      </geometry>
    </collision>
  </link>
  <joint name="rh6_right_fy11" type="revolute">
    <origin xyz="0.0135 0.022 0.0398" rpy="0 0 1.5708"/>
    <parent link="rh6_right_base_link"/>
    <child link="rh6_right_fy11_Link"/>
    <axis xyz="0 0 -1"/>
    <limit lower="0" upper="2.356" effort="0" velocity="0"/>
  </joint>
  <link name="rh6_right_fy12_Link">
    <inertial>
      <origin xyz="0.0171306597723995 0.00371896000224788 -4.99658958874605E-07" rpy="0 0 0"/>
      <mass value="0.0125497959072737"/>
      <inertia ixx="8.09093809009174E-07" ixy="-5.16426676935394E-07" ixz="2.07629840451354E-10" iyy="2.8318103299697E-06" iyz="-1.04479631329239E-11" izz="2.66845478314068E-06"/>
    </inertial>
    <visual>
      <origin xyz="0 0 0" rpy="0 0 0"/>
      <geometry>
        <mesh filename="package://robot_model/meshes/rh6_ctrl/fy12_Link.STL"/>
      </geometry>
      <material name="">
        <color rgba="0.898039215686275 0.917647058823529 0.929411764705882 1"/>
      </material>
    </visual>
    <collision>
      <origin xyz="0 0 0" rpy="0 0 0"/>
      <geometry>
        <mesh filename="package://robot_model/meshes/rh6_ctrl/fy12_Link.STL"/>
      </geometry>
    </collision>
  </link>
  <joint name="rh6_right_fy12" type="revolute">
    <origin xyz="0.0105 0 0.0107" rpy="1.5708 0 0"/>
    <parent link="rh6_right_fy11_Link"/>
    <child link="rh6_right_fy12_Link"/>
    <axis xyz="0 0 1"/>
    <limit lower="0" upper="0.698" effort="0" velocity="0"/>
  </joint>
  <link name="rh6_right_fy13_Link">
    <inertial>
      <origin xyz="0.015845249321244 0.00619315314516696 5.25376853488524E-06" rpy="0 0 0"/>
      <mass value="0.00766845638651249"/>
      <inertia ixx="7.70929332520153E-07" ixy="-6.47381862466734E-07" ixz="-6.278147845085E-10" iyy="1.36029006441949E-06" iyz="-3.09433620722497E-10" izz="1.64848714565387E-06"/>
    </inertial>
    <visual>
      <origin xyz="0 0 0" rpy="0 0 0"/>
      <geometry>
        <mesh filename="package://robot_model/meshes/rh6_ctrl/fy13_Link.STL"/>
      </geometry>
      <material name="">
        <color rgba="0.898039215686275 0.917647058823529 0.929411764705882 1"/>
      </material>
    </visual>
    <collision>
      <origin xyz="0 0 0" rpy="0 0 0"/>
      <geometry>
        <mesh filename="package://robot_model/meshes/rh6_ctrl/fy13_Link.STL"/>
      </geometry>
    </collision>
  </link>
  <joint name="rh6_right_fy13" type="revolute">
    <origin xyz="0.040457 0.011223 0" rpy="0 0 0"/>
    <parent link="rh6_right_fy12_Link"/>
    <child link="rh6_right_fy13_Link"/>
    <axis xyz="0 0 1"/>
    <limit lower="0" upper="1.169" effort="0" velocity="0"/>
  </joint>
  <link name="rh6_right_fy14_Link">
    <inertial>
      <origin xyz="6.84221826485754E-06 -0.00329677647236757 -0.0165004874842345" rpy="0 0 0"/>
      <mass value="0.00378673281389124"/>
      <inertia ixx="4.70044970141018E-07" ixy="-9.16610943606549E-13" ixz="9.80771602200776E-11" iyy="4.91875647343776E-07" iyz="-1.26714352849373E-07" izz="1.41742406291917E-07"/>
    </inertial>
    <visual>
      <origin xyz="0 0 0" rpy="0 0 0"/>
      <geometry>
        <mesh filename="package://robot_model/meshes/rh6_ctrl/fy14_Link.STL"/>
      </geometry>
      <material name="">
        <color rgba="0.298039215686275 0.298039215686275 0.298039215686275 1"/>
      </material>
    </visual>
    <collision>
      <origin xyz="0 0 0" rpy="0 0 0"/>
      <geometry>
        <mesh filename="package://robot_model/meshes/rh6_ctrl/fy14_Link.STL"/>
      </geometry>
    </collision>
  </link>
  <joint name="rh6_right_fy14" type="revolute">
    <origin xyz="0.036284 0.0268 0" rpy="-0.36834 1.5708 0"/>
    <parent link="rh6_right_fy13_Link"/>
    <child link="rh6_right_fy14_Link"/>
    <axis xyz="0 0 1"/>
    <limit lower="0" upper="0" effort="0" velocity="0"/>
  </joint>
  <link name="rh6_right_fy21_Link">
    <inertial>
      <origin xyz="0.0183100453576791 0.00110404248642637 1.4314615770783E-06" rpy="0 0 0"/>
      <mass value="0.0100639225371382"/>
      <inertia ixx="4.62549818532259E-07" ixy="-1.43111709269249E-07" ixz="-2.02961569671992E-10" iyy="2.22041671394316E-06" iyz="-7.34804871357593E-11" izz="2.08162847489449E-06"/>
    </inertial>
    <visual>
      <origin xyz="0 0 0" rpy="0 0 0"/>
      <geometry>
        <mesh filename="package://robot_model/meshes/rh6_ctrl/fy21_Link.STL"/>
      </geometry>
      <material name="">
        <color rgba="0.898039215686275 0.917647058823529 0.929411764705882 1"/>
      </material>
    </visual>
    <collision>
      <origin xyz="0 0 0" rpy="0 0 0"/>
      <geometry>
        <mesh filename="package://robot_model/meshes/rh6_ctrl/fy21_Link.STL"/>
      </geometry>
    </collision>
  </link>
  <joint name="rh6_right_fy21" type="revolute">
    <origin xyz="-0.0035 0.029833 0.11095" rpy="0 -1.4923 1.5708"/>
    <parent link="rh6_right_base_link"/>
    <child link="rh6_right_fy21_Link"/>
    <axis xyz="0 0 -1"/>
    <limit lower="0" upper="1.518" effort="0" velocity="0"/>
  </joint>
  <link name="rh6_right_fy22_Link">
    <inertial>
      <origin xyz="0.0162670548054254 0.000328335996538476 2.60886696606955E-07" rpy="0 0 0"/>
      <mass value="0.00358605495739092"/>
      <inertia ixx="1.44429039989069E-07" ixy="1.06001497335138E-07" ixz="5.32604155588992E-11" iyy="7.23506313818756E-07" iyz="-2.39237240611277E-11" izz="7.27978897340784E-07"/>
    </inertial>
    <visual>
      <origin xyz="0 0 0" rpy="0 0 0"/>
      <geometry>
        <mesh filename="package://robot_model/meshes/rh6_ctrl/fy22_Link.STL"/>
      </geometry>
      <material name="">
        <color rgba="0.658823529411765 0.619607843137255 0.56078431372549 1"/>
      </material>
    </visual>
    <collision>
      <origin xyz="0 0 0" rpy="0 0 0"/>
      <geometry>
        <mesh filename="package://robot_model/meshes/rh6_ctrl/fy22_Link.STL"/>
      </geometry>
    </collision>
  </link>
  <joint name="rh6_right_fy22" type="revolute">
    <origin xyz="0.0419 0.001 0" rpy="0 0 0"/>
    <parent link="rh6_right_fy21_Link"/>
    <child link="rh6_right_fy22_Link"/>
    <axis xyz="0 0 -1"/>
    <limit lower="0" upper="1.623" effort="0" velocity="0"/>
  </joint>
  <link name="rh6_right_fy23_Link">
    <inertial>
      <origin xyz="-5.03450954461582E-06 0.0035802558028295 -0.0177331035964679" rpy="0 0 0"/>
      <mass value="0.00260327905787072"/>
      <inertia ixx="3.22614347129068E-07" ixy="1.33060728534008E-11" ixz="-1.18853194129732E-10" iyy="3.1138821138318E-07" iyz="9.01404791757268E-08" izz="7.26722620152445E-08"/>
    </inertial>
    <visual>
      <origin xyz="0 0 0" rpy="0 0 0"/>
      <geometry>
        <mesh filename="package://robot_model/meshes/rh6_ctrl/fy23_Link.STL"/>
      </geometry>
      <material name="">
        <color rgba="0.298039215686275 0.298039215686275 0.298039215686275 1"/>
      </material>
    </visual>
    <collision>
      <origin xyz="0 0 0" rpy="0 0 0"/>
      <geometry>
        <mesh filename="package://robot_model/meshes/rh6_ctrl/fy23_Link.STL"/>
      </geometry>
    </collision>
  </link>
  <joint name="rh6_right_fy23" type="revolute">
    <origin xyz="0.043692 -0.011217 0" rpy="-1.5708 1.5695 -1.5543"/>
    <parent link="rh6_right_fy22_Link"/>
    <child link="rh6_right_fy23_Link"/>
    <axis xyz="0 0 -1"/>
    <limit lower="0" upper="0" effort="0" velocity="0"/>
  </joint>
  <link name="rh6_right_fy31_Link">
    <inertial>
      <origin xyz="0.0233371897488126 0.000590481232768836 1.05810883203883E-06" rpy="0 0 0"/>
      <mass value="0.00829865569529675"/>
      <inertia ixx="3.67197532035121E-07" ixy="-1.18935852306319E-07" ixz="-1.57676508902933E-10" iyy="2.37343189337524E-06" iyz="-3.77701441406405E-11" izz="2.26081333444121E-06"/>
    </inertial>
    <visual>
      <origin xyz="0 0 0" rpy="0 0 0"/>
      <geometry>
        <mesh filename="package://robot_model/meshes/rh6_ctrl/fy31_Link.STL"/>
      </geometry>
      <material name="">
        <color rgba="0.898039215686275 0.917647058823529 0.929411764705882 1"/>
      </material>
    </visual>
    <collision>
      <origin xyz="0 0 0" rpy="0 0 0"/>
      <geometry>
        <mesh filename="package://robot_model/meshes/rh6_ctrl/fy31_Link.STL"/>
      </geometry>
    </collision>
  </link>
  <joint name="rh6_right_fy31" type="revolute">
    <origin xyz="-0.0035 0.009945 0.112" rpy="0 -1.5446 1.5708"/>
    <parent link="rh6_right_base_link"/>
    <child link="rh6_right_fy31_Link"/>
    <axis xyz="0 0 -1"/>
    <limit lower="0" upper="1.571" effort="0" velocity="0"/>
  </joint>
  <link name="rh6_right_fy32_Link">
    <inertial>
      <origin xyz="0.0162682170798479 0.000256347166125992 3.06763353261075E-07" rpy="0 0 0"/>
      <mass value="0.00358603535605245"/>
      <inertia ixx="1.45378610271944E-07" ixy="1.08558752300259E-07" ixz="4.9849784513399E-11" iyy="7.22549183303638E-07" iyz="-2.43260136945764E-11" izz="7.27970697204602E-07"/>
    </inertial>
    <visual>
      <origin xyz="0 0 0" rpy="0 0 0"/>
      <geometry>
        <mesh filename="package://robot_model/meshes/rh6_ctrl/fy32_Link.STL"/>
      </geometry>
      <material name="">
        <color rgba="0.658823529411765 0.619607843137255 0.56078431372549 1"/>
      </material>
    </visual>
    <collision>
      <origin xyz="0 0 0" rpy="0 0 0"/>
      <geometry>
        <mesh filename="package://robot_model/meshes/rh6_ctrl/fy32_Link.STL"/>
      </geometry>
    </collision>
  </link>
  <joint name="rh6_right_fy32" type="revolute">
    <origin xyz="0.0519 0.001 0" rpy="0 0 0"/>
    <parent link="rh6_right_fy31_Link"/>
    <child link="rh6_right_fy32_Link"/>
    <axis xyz="0 0 -1"/>
    <limit lower="0" upper="1.641" effort="0" velocity="0"/>
  </joint>
  <link name="rh6_right_fy33_Link">
    <inertial>
      <origin xyz="-1.39419368525018E-06 0.0035802607719615 -0.0177330927084453" rpy="0 0 0"/>
      <mass value="0.00260328811165374"/>
      <inertia ixx="3.22618883425544E-07" ixy="3.93409844107229E-12" ixz="-3.33398326289438E-11" iyy="3.1139226640071E-07" iyz="9.01415489693662E-08" izz="7.26722969960641E-08"/>
    </inertial>
    <visual>
      <origin xyz="0 0 0" rpy="0 0 0"/>
      <geometry>
        <mesh filename="package://robot_model/meshes/rh6_ctrl/fy33_Link.STL"/>
      </geometry>
      <material name="">
        <color rgba="0.298039215686275 0.298039215686275 0.298039215686275 1"/>
      </material>
    </visual>
    <collision>
      <origin xyz="0 0 0" rpy="0 0 0"/>
      <geometry>
        <mesh filename="package://robot_model/meshes/rh6_ctrl/fy33_Link.STL"/>
      </geometry>
    </collision>
  </link>
  <joint name="rh6_right_fy33" type="revolute">
    <origin xyz="0.043641 -0.01141 0" rpy="-1.5708 1.5705 -1.5587"/>
    <parent link="rh6_right_fy32_Link"/>
    <child link="rh6_right_fy33_Link"/>
    <axis xyz="0 0 -1"/>
    <limit lower="0" upper="0" effort="0" velocity="0"/>
  </joint>
  <link name="rh6_right_fy41_Link">
    <inertial>
      <origin xyz="0.0183100300728871 0.00110404217386961 1.44331117438168E-06" rpy="0 0 0"/>
      <mass value="0.0100639366001575"/>
      <inertia ixx="4.62549940478248E-07" ixy="-1.43110929372667E-07" ixz="-2.04350361871807E-10" iyy="2.22041795607779E-06" iyz="-7.4833604536666E-11" izz="2.08162888617781E-06"/>
    </inertial>
    <visual>
      <origin xyz="0 0 0" rpy="0 0 0"/>
      <geometry>
        <mesh filename="package://robot_model/meshes/rh6_ctrl/fy41_Link.STL"/>
      </geometry>
      <material name="">
        <color rgba="0.898039215686275 0.917647058823529 0.929411764705882 1"/>
      </material>
    </visual>
    <collision>
      <origin xyz="0 0 0" rpy="0 0 0"/>
      <geometry>
        <mesh filename="package://robot_model/meshes/rh6_ctrl/fy41_Link.STL"/>
      </geometry>
    </collision>
  </link>
  <joint name="rh6_right_fy41" type="revolute">
    <origin xyz="-0.0035 -0.009945 0.11099" rpy="3.1416 -1.5446 -1.5708"/>
    <parent link="rh6_right_base_link"/>
    <child link="rh6_right_fy41_Link"/>
    <axis xyz="0 0 -1"/>
    <limit lower="0" upper="1.571" effort="0" velocity="0"/>
  </joint>
  <link name="rh6_right_fy42_Link">
    <inertial>
      <origin xyz="0.0162664773528961 0.000328549470069661 7.07663118645896E-07" rpy="0 0 0"/>
      <mass value="0.00358590544643104"/>
      <inertia ixx="1.44429028630629E-07" ixy="1.05993747396946E-07" ixz="3.0696952809912E-11" iyy="7.23463970805304E-07" iyz="-3.0630296311014E-11" izz="7.2793510267497E-07"/>
    </inertial>
    <visual>
      <origin xyz="0 0 0" rpy="0 0 0"/>
      <geometry>
        <mesh filename="package://robot_model/meshes/rh6_ctrl/fy42_Link.STL"/>
      </geometry>
      <material name="">
        <color rgba="0.658823529411765 0.619607843137255 0.56078431372549 1"/>
      </material>
    </visual>
    <collision>
      <origin xyz="0 0 0" rpy="0 0 0"/>
      <geometry>
        <mesh filename="package://robot_model/meshes/rh6_ctrl/fy42_Link.STL"/>
      </geometry>
    </collision>
  </link>
  <joint name="rh6_right_fy42" type="revolute">
    <origin xyz="0.0419 0.001 0" rpy="0 0 0"/>
    <parent link="rh6_right_fy41_Link"/>
    <child link="rh6_right_fy42_Link"/>
    <axis xyz="0 0 -1"/>
    <limit lower="0" upper="1.658" effort="0" velocity="0"/>
  </joint>
  <link name="rh6_right_fy43_Link">
    <inertial>
      <origin xyz="1.8119656877702E-06 0.00358031778281198 -0.0177332688467031" rpy="0 0 0"/>
      <mass value="0.00260331123444047"/>
      <inertia ixx="3.22618912285256E-07" ixy="2.25533804931156E-12" ixz="1.89822416951554E-11" iyy="3.11392219554833E-07" iyz="9.01422800314552E-08" izz="7.26739626112056E-08"/>
    </inertial>
    <visual>
      <origin xyz="0 0 0" rpy="0 0 0"/>
      <geometry>
        <mesh filename="package://robot_model/meshes/rh6_ctrl/fy43_Link.STL"/>
      </geometry>
      <material name="">
        <color rgba="0.298039215686275 0.298039215686275 0.298039215686275 1"/>
      </material>
    </visual>
    <collision>
      <origin xyz="0 0 0" rpy="0 0 0"/>
      <geometry>
        <mesh filename="package://robot_model/meshes/rh6_ctrl/fy43_Link.STL"/>
      </geometry>
    </collision>
  </link>
  <joint name="rh6_right_fy43" type="revolute">
    <origin xyz="0.043692 -0.011217 0" rpy="1.5708 1.5704 1.5873"/>
    <parent link="rh6_right_fy42_Link"/>
    <child link="rh6_right_fy43_Link"/>
    <axis xyz="0 0 -1"/>
    <limit lower="0" upper="0" effort="0" velocity="0"/>
  </joint>
  <link name="rh6_right_fy51_Link">
    <inertial>
      <origin xyz="0.0158684874364952 0.00100262567201714 1.32109851685991E-06" rpy="0 0 0"/>
      <mass value="0.00870573306563604"/>
      <inertia ixx="3.93124157202167E-07" ixy="-1.16969683848895E-07" ixz="-1.45438947668994E-10" iyy="1.63160442433223E-06" iyz="-5.82112463619306E-11" izz="1.50798061279593E-06"/>
    </inertial>
    <visual>
      <origin xyz="0 0 0" rpy="0 0 0"/>
      <geometry>
        <mesh filename="package://robot_model/meshes/rh6_ctrl/fy51_Link.STL"/>
      </geometry>
      <material name="">
        <color rgba="0.898039215686275 0.917647058823529 0.929411764705882 1"/>
      </material>
    </visual>
    <collision>
      <origin xyz="0 0 0" rpy="0 0 0"/>
      <geometry>
        <mesh filename="package://robot_model/meshes/rh6_ctrl/fy51_Link.STL"/>
      </geometry>
    </collision>
  </link>
  <joint name="rh6_right_fy51" type="revolute">
    <origin xyz="-0.0035 -0.029624 0.10795" rpy="3.1416 -1.4923 -1.5708"/>
    <parent link="rh6_right_base_link"/>
    <child link="rh6_right_fy51_Link"/>
    <axis xyz="0 0 -1"/>
    <limit lower="0" upper="1.545" effort="0" velocity="0"/>
  </joint>
  <link name="rh6_right_fy52_Link">
    <inertial>
      <origin xyz="0.016266391799061 0.000328448417603933 7.642167395433E-07" rpy="0 0 0"/>
      <mass value="0.00358587967262367"/>
      <inertia ixx="1.44430764836659E-07" ixy="1.05997793149172E-07" ixz="2.74809999522819E-11" iyy="7.23455258661051E-07" iyz="-3.03898403226654E-11" izz="7.27927913373667E-07"/>
    </inertial>
    <visual>
      <origin xyz="0 0 0" rpy="0 0 0"/>
      <geometry>
        <mesh filename="package://robot_model/meshes/rh6_ctrl/fy52_Link.STL"/>
      </geometry>
      <material name="">
        <color rgba="0.658823529411765 0.619607843137255 0.56078431372549 1"/>
      </material>
    </visual>
    <collision>
      <origin xyz="0 0 0" rpy="0 0 0"/>
      <geometry>
        <mesh filename="package://robot_model/meshes/rh6_ctrl/fy52_Link.STL"/>
      </geometry>
    </collision>
  </link>
  <joint name="rh6_right_fy52" type="revolute">
    <origin xyz="0.0369 0.001 0" rpy="0 0 0"/>
    <parent link="rh6_right_fy51_Link"/>
    <child link="rh6_right_fy52_Link"/>
    <axis xyz="0 0 -1"/>
    <limit lower="0" upper="1.658" effort="0" velocity="0"/>
  </joint>
  <link name="rh6_right_fy53_Link">
    <inertial>
      <origin xyz="5.01050953573279E-06 0.0035804146644185 -0.0177336047185497" rpy="0 0 0"/>
      <mass value="0.00260328769879583"/>
      <inertia ixx="3.22604577356363E-07" ixy="-6.35251503937563E-12" ixz="9.59700559637986E-11" iyy="3.11380365618274E-07" iyz="9.01380370887452E-08" izz="7.26739997568638E-08"/>
    </inertial>
    <visual>
      <origin xyz="0 0 0" rpy="0 0 0"/>
      <geometry>
        <mesh filename="package://robot_model/meshes/rh6_ctrl/fy53_Link.STL"/>
      </geometry>
      <material name="">
        <color rgba="0.298039215686275 0.298039215686275 0.298039215686275 1"/>
      </material>
    </visual>
    <collision>
      <origin xyz="0 0 0" rpy="0 0 0"/>
      <geometry>
        <mesh filename="package://robot_model/meshes/rh6_ctrl/fy53_Link.STL"/>
      </geometry>
    </collision>
  </link>
  <joint name="rh6_right_fy53" type="revolute">
    <origin xyz="0.043691 -0.011217 0" rpy="1.5708 1.5695 1.5873"/>
    <parent link="rh6_right_fy52_Link"/>
    <child link="rh6_right_fy53_Link"/>
    <axis xyz="0 0 -1"/>
    <limit lower="0" upper="0" effort="0" velocity="0"/>
  </joint>
  <link name="rh6_right_grasp_center">
    <visual>
      <origin xyz="0 0 0" rpy="0 0 0"/>
      <geometry>
        <sphere radius="0.002"/>
      </geometry>
      <material name="grasp_center_green">
        <color rgba="0 1 0 1"/>
      </material>
    </visual>
  </link>
  <joint name="rh6_right_grasp_center_joint" type="fixed">
    <parent link="rh6_right_base_link"/>
    <child link="rh6_right_grasp_center"/>
    <origin xyz="0.02 0 0.1" rpy="0 0 0"/>
  </joint>
</robot>
